Workbook
Name A: PAYROLL!#REF!
Name aug15b: #REF!
Name mes: #REF!
Name Sept30: #REF!
Name Tax_Code: #REF!
Name Taxable_Income: #REF!

Sheet PAYROLL
C1: SUMINAC PHILIPPINES, INC. | CN1: SUMINAC PHILIPPINES, INC.
C2: RANK & FILE PAYROLL 2023 | F2: 30 AUGUST 2023 | N2: NEW MEMBERS | T2: 1 | U2: 1.3 | V2: 1.9 | W2: 1.3 | AM2: 1.3 | AN2: 1.3 | AO2: 1.5 | AP2: 2.3 | CN2: RANK & FILE PAYROLL 2019 | DI2: note:
C3: =VLOOKUP(F2,'[1]DATE lookup'!E:H,4,FALSE) -> (11 - 25 AUG, 2023) | N3: OFF SHORE | AM3: RD | AN3: 1.9 | AP3: 2.9 | BN3: updated 3/27/19 | BS3: =LEFT($F$2,2) -> 30 | BT3: =LEFT($F$2,2) -> 30 | BU3: =LEFT($F$2,2) -> 30 | BW3: =LEFT($F$2,2) -> 30 | BY3: =LEFT($F$2,2) -> 30 | BZ3: =LEFT($F$2,2) -> 30 | CN3: SSS/ PHIC/ HDMF CONTRIBUTION | DI3: =LEFT($F$2,2) -> 30 | DJ3: =LEFT($F$2,2) -> 30 | DK3: =LEFT($F$2,2) -> 30 | DL3: =LEFT($F$2,2) -> 30
AM4: old rate | AN4: 5
N5: ML / RESIGNED | O5: 116 | P5: REGULAR HOURS THIS PERIOD | AI5: a | AK5: b | AL5: c | AM5: d | AN5: e | AO5: f | AP5: g | AQ5: h | AR5: i | AW5: j | AX5: t | AY5: l | BA5: m | BC5: n | BD5: o | BE5: p | BF5: q | BG5: s | BH5: r | BN5: k | BP5: u = sum(a:t) | BR5: w | BS5: x | BT5: y | BU5: z | BW5: aa | BY5: ab | BZ5: ac | CA5: ae | CD5: ad | CE5: af | CF5: ag | CG5: ah | CH5: ai = sum(w:ah) | CI5: ak = u - ai | CJ5: aj | CQ5: IMPORTANT | DW5: =L5*1.8 -> 0 | DX5: 90000 | DY5: =IF(DW5>DX5,DW5-DX5,0) -> 0 | DZ5: =DY5/24 -> 0
B6: Line | D6: 1 | E6: 2 | F6: 3 | G6: 4 | H6: 5 | I6: 6 | J6: 7 | K6: 8 | L6: 9 | M6: 10 | N6: 11 | O6: 12 | P6: 13 | Q6: 14 | R6: 15 | S6: 16 | T6: 17 | U6: 18 | V6: 19 | W6: 20 | X6: 21 | Y6: 22 | Z6: 23 | AA6: 24 | AB6: 25 | AC6: 26 | AD6: 27 | AE6: 28 | AF6: 29 | AG6: 30 | AH6: 31 | AI6: 32 | AJ6: 33 | AK6: 34 | AL6: 35 | AM6: 36 | AN6: 37 | AO6: 38 | AP6: 39 | AQ6: 40 | AR6: 41 | AS6: 42 | AT6: 43 | AU6: 44 | AV6: 45 | AW6: 46 | AX6: 47 | AY6: 48 | AZ6: 49 | BA6: 50 | BB6: 51 | BC6: 52 | BD6: 53 | BE6: 54 | BF6: 55 | BG6: 56 | BH6: 57 | BI6: 58 | BJ6: 59 | BK6: 60 | BL6: 61 | BM6: 62 | BN6: 63 | BO6: 64 | BP6: 65 | BQ6: 66 | BR6: 67 | BS6: 68 | BT6: 69 | BU6: 70 | BV6: 71 | BW6: 72 | BX6: 73 | BY6: 74 | BZ6: 75 | CA6: 76 | CB6: 77 | CC6: 78 | CD6: 79 | CE6: 80 | CF6: 81 | CG6: 82 | CH6: 83 | CI6: 84 | CJ6: 85 | CK6: 86 | CL6: 87 | CM6: 88 | CN6: 89 | CO6: 90 | CP6: 91 | CQ6: 92 | CR6: 93 | CS6: 94 | CT6: 95 | CU6: 96 | CV6: 97 | CW6: 98 | CX6: 99 | CY6: 100 | CZ6: 101 | DA6: 102 | DB6: 103 | DC6: 104 | DD6: 105 | DE6: 106 | DF6: 107 | DG6: 108 | DH6: 109 | DI6: 110 | DJ6: 111 | DK6: 112 | DL6: 113 | DM6: 114 | DN6: 115 | DO6: 116 | DP6: 117 | DQ6: 118 | DR6: 119 | DS6: 120 | DT6: 121 | DU6: 122 | DV6: 123 | DW6: 124 | DX6: 125 | DY6: 126 | DZ6: 127 | EA6: 128 | EB6: 129 | EC6: 130 | ED6: 131
P7: ACTUAL HOURS | AG7: TAXABLE INCOME | BC7: 0 | BS7: GOVT CONTRI | BW7: GOVT LOANS | CA7: COMPANY | CE7: OTHERS | CQ7: 15TH PAYROLL | CT7: SSS | CZ7: PHILHEALTH | DE7: PAGIBIG | DI7: LOANS | DM7: WITHHOLDING TAXES | EA7: EMPLOYER GOVT CONTRIBUTION
A8: PAYSLIP NO | B8: Seq. No. | C8: DEPT. | D8: ID No. | E8: NAME | F8: SECTION | G8: LOCATION | H8: DATE HIRED | I8: TITLE | J8: TYPE | K8: TAX CODE | L8: EQUIV. MONTHLY RATE | M8: DAILY RATE | N8: NEW DAILY RATE | O8: No. of Hrs (Factor) | P8: ST (Hours) | Q8: No. of Hrs Absent | R8: SWAP (Hours) | S8: Regular OT (ROT) Hours | T8: REST DAY OT 130% (Hours) | U8: Excess OT on RestDay (Hours) | V8: ND (Hours) | W8: Half Month Rate | X8: Absent Amount | Y8: ST Amount | Z8: SWAP | AA8: Regular OT (ROT) Amount | AB8: REST DAY OT 130% (Amount) | AC8: Excess OT on RestDay (Amount) | AD8: ND Amount | AE8: Add'tl benefit - Allowance | AF8: Other Taxable Adjustment | AG8: TOTAL TAXABLE INCOME | AH8: OT Meal Allow | AI8: Rice Subsidy/ Allowance | AJ8: CTPA | AK8: SEA | AL8: Transpo Allow | AM8: SWC Amount | AN8: FREE LUNCH | AO8: Medical Reimbursement | AP8: Other Benefit - Non Tax Allowance | AQ8: Other Adjustment (Non Taxable) | AR8: TOTAL NON-TAXABLE INCOME | AS8: GROSS PAY | AT8: W/Hold Tax | AU8: SSS Contri | AV8: Philhealth Contri | AW8: SSS Salary Loan | AX8: SSS Calamity Loan | AY8: HDMF MPL Loan | AZ8: HDMF CAL Loan | BA8: Health Card | BB8: CMCL | BC8: Other Company Deduction | BD8: Canteen | BE8: Coop | BF8: RCBC Loan | BG8: TOTAL DEDUCTION | BH8: NET PAY | BI8: Account Number | BJ8: MONTH | BK8: PERIOD | BL8: BASIC PAY FOR 13TH MO | BM8: ID No. | BN8: NAME | BO8: MONTHLY INCOME FOR PHIC | BP8: GROSS PAY 15TH | BQ8: GROSS PAY 30TH | BR8: TOTAL GROSS PAY | BS8: SSS | BT8: SSS | BU8: SSS | BV8: SSS | BW8: SSS | BX8: SSS Contribution | BY8: PHIC | BZ8: PHIC | CA8: PHIC | CB8: PHIC | CC8: Philhealth Contribution | CD8: Pagibig Contribution | CE8: Pagibig Contribution2 | CF8: Pagibig TOTAL | CG8: Modified Pag-ibig II | CH8: SSS SALARY | CI8: SSS CALAMITY | CJ8: HDMF MPL Loan | CK8: HDMF CAL Loan | CL8: Taxable Income | CM8: Mandatory Contribution | CN8: Taxable Income | CO8: Tax Code | CP8: Compensation Level | CQ8: Tax due on Compensation Level | CR8: Excess on Compensation Level | CS8: Tax Rate on Excess | CT8: Tax Due on Excess | CU8: TOTAL Tax Due | CV8: ESTIMATED 13TH MO & BONUS 190% (ACTUAL 170%-194%) | CW8: BIR CEILING on 13TH MONTH & OTHER BONUS | CX8: TAXABLE (EXCESS) | CY8: ADDITIONAL TAXABLE PER PAYROLL | CZ8: SSS EMPLOYER SHARE | DA8: Philhealth EMPLOYER SHARE | DB8: Pagibig EMPLOYER SHARE | DC8: TOTAL EMPLOYER SHARE | DD8: TOTAL OT HOURS | DE8: TOTAL OT COST | DF8: STATUS | DG8: TAX REFUND | DH8: Modified Pag-ibig II | DI8: SSS SALARY | DJ8: SSS CALAMITY | DK8: HDMF MPL Loan | DL8: HDMF CAL Loan | DM8: Taxable Income | DN8: Mandatory Contribution | DO8: Taxable Income | DP8: Tax Code | DQ8: Compensation Level | DR8: Tax due on Compensation Level | DS8: Excess on Compensation Level | DT8: Tax Rate on Excess | DU8: Tax Due on Excess | DV8: TOTAL Tax Due | DW8: ESTIMATED 13TH MO & BONUS 190% (ACTUAL 170%-194%) | DX8: BIR CEILING on 13TH MONTH & OTHER BONUS | DY8: TAXABLE (EXCESS) | DZ8: ADDITIONAL TAXABLE PER PAYROLL | EA8: SSS EMPLOYER SHARE | EB8: Philhealth EMPLOYER SHARE | EC8: Pagibig EMPLOYER SHARE | ED8: TOTAL EMPLOYER SHARE
A9: 1 | B9: 1 | C9: 20 | D9: 1668 | E9: Ilagan,Roselle | F9: Production Control | G9: SN TRAINEE | H9: 43413 | J9: Semi-Mo. | K9: S | L9: =N9*26.17 -> 16035.668 | N9: 612.75 | O9: 116 | P9: 116 | Q9: 0 | R9: 0 | S9: 0 | T9: 0 | U9: 0 | V9: 0 | W9: 8017.8338 | X9: 0 | Y9: 8017.83 | Z9: 0 | AA9: 0 | AB9: 0 | AC9: 0 | AD9: 0 | AE9: 0 | AF9: 0 | AG9: 8017.83 | AH9: 0 | AI9: 144 | AJ9: 0 | AK9: 0 | AL9: 0 | AM9: 0 | AN9: 0 | AO9: 0 | AP9: 0 | AQ9: 0 | AR9: 144 | AS9: 8161.83 | AT9: 0 | AU9: 0 | AV9: 0 | AW9: 0 | AX9: 0 | AY9: 0 | AZ9: 0 | BA9: 0 | BB9: 0 | BC9: 40 | BD9: 0 | BE9: 600 | BF9: 0 | BG9: 640 | BH9: 7521.83 | BI9: 9026605917 | BJ9: AUG 2023 | BK9: 30 AUGUST 2023 | BL9: 8017.83 | BM9: 1668 | BN9: Ilagan,Roselle | BO9: 16035.668 | BP9: 8161.83 | BR9: 8161.83 | BS9: 0 | BT9: 0 | BU9: 0 | BV9: 0 | BW9: 360 | BX9: 360 | CC9: 320.71 | CD9: 100 | CF9: 100 | CH9: 0 | CI9: 0 | CJ9: 0 | CK9: 0 | CL9: 8017.83 | CM9: 0 | CN9: 8017.83 | CO9: M | CP9: 0 | CQ9: 0 | CR9: 0 | CS9: 0 | CT9: 0 | CU9: 0 | CZ9: 0 | DA9: 0 | DB9: 0 | DC9: 0 | DD9: 0 | DE9: 0 | DI9: =IF(DI$3="15",SUMIF([1]Deductions!C:C,PAYROLL!D9,[1]Deductions!Q:Q),0) -> 0 | DJ9: =IF(DJ$3="30",SUMIF([1]Deductions!C:C,PAYROLL!D9,[1]Deductions!R:R),0) -> #VALUE! | DK9: =IF(DK$3="15",SUMIF([1]Deductions!C:C,PAYROLL!D9,[1]Deductions!S:S),0) -> 0 | DL9: =IF(DL$3="15",SUMIF([1]Deductions!C:C,PAYROLL!D9,[1]Deductions!T:T),0) -> 0 | DM9: =BB9 -> 0 | DN9: =-BS9-BT9-IF(BU9>0,100,0) -> 0 | DO9: =BB9-BS9-BT9-IF(BU9>0,100,0) -> 0 | DP9: M | DQ9: =IF(DO9>333333,333333,IF(DO9>83333,83333,IF(DO9>33333,33333,IF(DO9>16667,16667,IF(DO9>10417,10417,0))))) -> 0 | DR9: =IF(DO9>333333,91770.7,IF(DO9>83333,16770.7,IF(DO9>33333,4270.7,IF(DO9>16667,937.5,IF(DO9>10417,0,0))))) -> 0 | DS9: =IF(DQ9=0,0,DO9-DQ9) -> 0 | DT9: =IF(DO9>333333,0.35,IF(DO9>83333,0.3,IF(DO9>33333,0.25,IF(DO9>16667,0.2,IF(DO9>10417,0.15,0))))) -> 0 | DU9: =DT9*DS9 -> 0 | DV9: =ROUND(DR9+DU9,2) -> 0 | EA9: =IF(BT9>0,IF(ISERROR(VLOOKUP(CY9,'[1]SSS table 2021'!N:Q,4,FALSE)),0,(VLOOKUP(CY9,'[1]SSS table 2021'!N:Q,4,FALSE))),0) -> 0 | EB9: =IF(BT9>0,BT9,0) -> 0 | EC9: =IF(BU9>0,100,0) -> 0 | ED9: =SUM(EA9:EC9) -> 0
A10: 2 | B10: =+B9+1 -> 2 | C10: 20 | D10: 758 | E10: Ugsang, John Ryuchie | F10: Maintenance | H10: 39374 | I10: TL 1 | J10: Semi-Mo. | K10: M4 | L10: =N10*26.17 -> 20170.528 | N10: 770.75 | O10: 116 | P10: 116 | Q10: 0 | R10: 0 | S10: 0 | T10: 8 | U10: 0 | V10: 0 | W10: 10085.264 | X10: 0 | Y10: 10085.26 | Z10: 0 | AA10: 0 | AB10: 1001.98 | AC10: 0 | AD10: 0 | AE10: 437 | AF10: 0 | AG10: 11524.24 | AH10: 36 | AI10: 144 | AJ10: 193.75 | AK10: 0 | AL10: 0 | AM10: 0 | AN10: 0 | AO10: 0 | AP10: 805.5 | AQ10: 0 | AR10: 1179.25 | AS10: 12703.49 | AT10: 166.09 | AU10: 0 | AV10: 0 | AW10: 0 | AX10: 0 | AY10: 0 | AZ10: 749.01 | BA10: 1363.54 | BB10: 0 | BC10: 852.5 | BD10: 584 | BE10: 400 | BF10: 0 | BG10: 4115.14 | BH10: 8588.35 | BI10: 1358695457 | BJ10: AUG 2023 | BK10: 30 AUGUST 2023 | BL10: 11087.24 | BM10: 758 | BN10: Ugsang, John Ryuchie | BO10: 20170.528 | BP10: 12703.49 | BR10: 12703.49 | BS10: 0 | BT10: 0 | BU10: 0 | BV10: 562.5 | BW10: 0 | BX10: 562.5 | CC10: 403.41 | CD10: 100 | CF10: 100 | CH10: 0 | CI10: 0 | CJ10: 0 | CK10: 749.01 | CL10: 11524.24 | CM10: 0 | CN10: 11524.24 | CO10: M | CP10: 10417 | CQ10: 0 | CR10: 1107.24 | CS10: 0.15 | CT10: 166.086 | CU10: 166.09 | CZ10: 0 | DA10: 0 | DB10: 0 | DC10: 0 | DD10: 0 | DE10: 0 | DI10: =IF(DI$3="15",SUMIF([1]Deductions!C:C,PAYROLL!D10,[1]Deductions!Q:Q),0) -> 0 | DJ10: =IF(DJ$3="30",SUMIF([1]Deductions!C:C,PAYROLL!D10,[1]Deductions!R:R),0) -> #VALUE! | DK10: =IF(DK$3="15",SUMIF([1]Deductions!C:C,PAYROLL!D10,[1]Deductions!S:S),0) -> 0 | DL10: =IF(DL$3="15",SUMIF([1]Deductions!C:C,PAYROLL!D10,[1]Deductions!T:T),0) -> 0 | DM10: =BB10 -> 0 | DN10: =-BS10-BT10-IF(BU10>0,100,0) -> 0 | DO10: =BB10-BS10-BT10-IF(BU10>0,100,0) -> 0 | DP10: M | DQ10: =IF(DO10>333333,333333,IF(DO10>83333,83333,IF(DO10>33333,33333,IF(DO10>16667,16667,IF(DO10>10417,10417,0))))) -> 0 | DR10: =IF(DO10>333333,91770.7,IF(DO10>83333,16770.7,IF(DO10>33333,4270.7,IF(DO10>16667,937.5,IF(DO10>10417,0,0))))) -> 0 | DS10: =IF(DQ10=0,0,DO10-DQ10) -> 0 | DT10: =IF(DO10>333333,0.35,IF(DO10>83333,0.3,IF(DO10>33333,0.25,IF(DO10>16667,0.2,IF(DO10>10417,0.15,0))))) -> 0 | DU10: =DT10*DS10 -> 0 | DV10: =ROUND(DR10+DU10,2) -> 0 | EA10: =IF(BT10>0,IF(ISERROR(VLOOKUP(CY10,'[1]SSS table 2021'!N:Q,4,FALSE)),0,(VLOOKUP(CY10,'[1]SSS table 2021'!N:Q,4,FALSE))),0) -> 0 | EB10: =IF(BT10>0,BT10,0) -> 0 | EC10: =IF(BU10>0,100,0) -> 0 | ED10: =SUM(EA10:EC10) -> 0
A11: 3 | B11: =+B10+1 -> 3 | C11: 30 | D11: 588 | E11: Rotairo, Jennifer | F11: Quality Control | H11: 38476 | J11: Daily | K11: M2 | N11: 569.75 | O11: 116 | P11: 116 | Q11: 0 | R11: 0 | S11: 20 | T11: 24 | U11: 0 | V11: 0 | W11: 0 | X11: 0 | Y11: 8261.38 | Z11: 0 | AA11: 1780.47 | AB11: 2222.03 | AC11: 0 | AD11: 0 | AE11: 0 | AF11: 0 | AG11: 12263.88 | AH11: 324 | AI11: 180 | AJ11: 218.75 | AK11: 0 | AL11: 0 | AM11: 0 | AN11: 0 | AO11: 0 | AP11: 0 | AQ11: 0 | AR11: 722.75 | AS11: 12986.63 | AT11: 277.03 | AU11: 0 | AV11: 0 | AW11: 1199.77 | AX11: 0 | AY11: 1119.18 | AZ11: 0 | BA11: 272.71 | BB11: 0 | BC11: 690 | BD11: 1500 | BE11: 2883.33 | BF11: 0 | BG11: 7942.02 | BH11: 5044.61 | BI11: 9021896816 | BJ11: AUG 2023 | BK11: 30 AUGUST 2023 | BL11: 10483.41 | BM11: 588 | BN11: Rotairo, Jennifer | BO11: 14910.358 | BP11: 12986.63 | BR11: 12986.63 | BS11: 0 | BT11: 0 | BU11: 0 | BV11: 585 | BW11: 0 | BX11: 585 | CC11: 298.21 | CD11: 100 | CF11: 100 | CH11: 1199.77 | CI11: 0 | CJ11: 1119.18 | CK11: 0 | CL11: 12263.88 | CM11: 0 | CN11: 12263.88 | CO11: M | CP11: 10417 | CQ11: 0 | CR11: 1846.88 | CS11: 0.15 | CT11: 277.032 | CU11: 277.03 | CZ11: 0 | DA11: 0 | DB11: 0 | DC11: 0 | DD11: 20 | DE11: 1780.47 | DI11: =IF(DI$3="15",SUMIF([1]Deductions!C:C,PAYROLL!D11,[1]Deductions!Q:Q),0) -> 0 | DJ11: =IF(DJ$3="30",SUMIF([1]Deductions!C:C,PAYROLL!D11,[1]Deductions!R:R),0) -> #VALUE! | DK11: =IF(DK$3="15",SUMIF([1]Deductions!C:C,PAYROLL!D11,[1]Deductions!S:S),0) -> 0 | DL11: =IF(DL$3="15",SUMIF([1]Deductions!C:C,PAYROLL!D11,[1]Deductions!T:T),0) -> 0 | DM11: =BB11 -> 0 | DN11: =-BS11-BT11-IF(BU11>0,100,0) -> 0 | DO11: =BB11-BS11-BT11-IF(BU11>0,100,0) -> 0 | DP11: M | DQ11: =IF(DO11>333333,333333,IF(DO11>83333,83333,IF(DO11>33333,33333,IF(DO11>16667,16667,IF(DO11>10417,10417,0))))) -> 0 | DR11: =IF(DO11>333333,91770.7,IF(DO11>83333,16770.7,IF(DO11>33333,4270.7,IF(DO11>16667,937.5,IF(DO11>10417,0,0))))) -> 0 | DS11: =IF(DQ11=0,0,DO11-DQ11) -> 0 | DT11: =IF(DO11>333333,0.35,IF(DO11>83333,0.3,IF(DO11>33333,0.25,IF(DO11>16667,0.2,IF(DO11>10417,0.15,0))))) -> 0 | DU11: =DT11*DS11 -> 0 | DV11: =ROUND(DR11+DU11,2) -> 0 | EA11: =IF(BT11>0,IF(ISERROR(VLOOKUP(CY11,'[1]SSS table 2021'!N:Q,4,FALSE)),0,(VLOOKUP(CY11,'[1]SSS table 2021'!N:Q,4,FALSE))),0) -> 0 | EB11: =IF(BT11>0,BT11,0) -> 0 | EC11: =IF(BU11>0,100,0) -> 0 | ED11: =SUM(EA11:EC11) -> 0
BR16: Prepared By: | BX16: Checked by: | CD16: Reviewed By: | CI16: Approved By:

Sheet PRINT
Q1: 1 | T1: 1
A2: 1 | D2: SUMINAC PHILIPPINES, INC. | T2: 2
C3: 1668 | D3: Ilagan,Roselle | M3: (11 - 25 AUG, 2023) | P3: 30 AUGUST 2023 | R3: CHECKING | S3: VARIANCE | T3: 3
C4: Section : | D4: Production Control | P4: No. 0001 | T4: 4
T5: 5
T6: 6
C7: TAXABLE COMPENSATION | F7: Hours | G7: Amount | I7: NON TAXABLE ALLOWANCE & BENEFITS | N7: DEDUCTIONS | T7: 7
C8: Basic Pay | E8: : | I8: OT Meal allowance | K8: : | N8: Adjustment | O8: : | T8: 8
C9: Less: Absences/SWAP (monthly) | E9: : | I9: Rice subsidy | K9: : | N9: W/holding Tax | O9: : | T9: 9
C10: SWAP | E10: : | I10: CTPA | K10: : | N10: SSS contribution | O10: : | T10: 10
C11: Regular OT (125%) | E11: : | I11: SEA | K11: : | N11: Philhealth contribution | O11: : | T11: 11
C12: Rest Day OT (130%) | E12: : | I12: Transportation allow. | K12: : | N12: Pag-ibig contri/Pag-ibig 2 | O12: : | T12: 12
C13: Excess OT on RD (30%) | E13: : | I13: SWC | K13: : | N13: SSS loan | O13: : | T13: 13
C14: Legal/Co. Holiday No work (100%) | E14: : | I14: Free Lunch | K14: : | N14: Pag-ibig MPL | O14: : | T14: 14
C15: Legal holiday (w/ work) | E15: : | I15: Medical | K15: : | N15: Pag-ibig Calamity Loan | O15: : | T15: 15
C16: Special/Co. holiday on WD | E16: : | N16: Health Card | O16: : | T16: 16
C17: Special/Co. Holiday on RD | E17: : | K17: : | N17: CMCL | O17: : | T17: 17
C18: Night Differential (10%) | E18: : | I18: 13TH Mo/ Bonus | K18: : | N18: Welfare contribution | O18: : | T18: 18
C19: Additional benefit | E19: : | I19: Additional benefit | K19: : | N19: Other deductions | O19: : | T19: 19
C20: SL/IL conversion (over 10 days) | E20: : | I20: SL/IL (<10 days) | K20: : | N20: Canteen | O20: : | T20: 20
C21: Taxable Adjustments | E21: : | I21: Other Adjustments | K21: : | N21: COOP | O21: : | T21: 21
C22: TOTAL TAXABLE | I22: TOTAL NON TAXABLE | N22: RCBC Loan | O22: : | T22: 22
I23: GROSS PAY | N23: TOTAL DEDUCTION | Q23: GR | R23: 8017.83 | S23: 0 | T23: 23
C24: Accumulated Taxable Income | E24: : | Q24: DE | R24: 1180.71 | S24: 0 | T24: 24
C25: Accumumlated W/TAX | E25: : | I25: Total IL/SL conversion | N25: NET PAY | Q25: NET | R25: 6837.12 | S25: 0 | T25: 25
T26: 26
T27: 27
T28: 28
T29: 29
T30: 30
T31: 31
T32: 32
T33: 33
A34: 2 | D34: SUMINAC PHILIPPINES, INC. | T34: 34
C35: 758 | D35: Ugsang, John Ryuchie | M35: (11 - 25 AUG, 2023) | P35: 30 AUGUST 2023 | T35: 35
C36: Section : | D36: Maintenance | P36: No. 0002 | T36: 36
T37: 37
T38: 38
C39: TAXABLE COMPENSATION | F39: Hours | G39: Amount | I39: NON TAXABLE ALLOWANCE & BENEFITS | N39: DEDUCTIONS | T39: 39
C40: Basic Pay | E40: : | I40: OT Meal allowance | N40: Adjustment | O40: : | T40: 40
...
